[2025-08-27T22:41:49.011+0500] {local_task_job_runner.py:120} INFO - ::group::Pre task execution logs
[2025-08-27T22:41:49.020+0500] {taskinstance.py:2076} INFO - Dependencies all met for dep_context=non-requeueable deps ti=<TaskInstance: etl_csv_pipeline.transform_task manual__2025-08-27T17:41:30.969743+00:00 [queued]>
[2025-08-27T22:41:49.023+0500] {taskinstance.py:2076} INFO - Dependencies all met for dep_context=requeueable deps ti=<TaskInstance: etl_csv_pipeline.transform_task manual__2025-08-27T17:41:30.969743+00:00 [queued]>
[2025-08-27T22:41:49.023+0500] {taskinstance.py:2306} INFO - Starting attempt 1 of 3
[2025-08-27T22:41:49.029+0500] {taskinstance.py:2330} INFO - Executing <Task(PythonOperator): transform_task> on 2025-08-27 17:41:30.969743+00:00
[2025-08-27T22:41:49.035+0500] {standard_task_runner.py:63} INFO - Started process 74427 to run task
[2025-08-27T22:41:49.040+0500] {standard_task_runner.py:90} INFO - Running: ['airflow', 'tasks', 'run', 'etl_csv_pipeline', 'transform_task', 'manual__2025-08-27T17:41:30.969743+00:00', '--job-id', '6', '--raw', '--subdir', 'DAGS_FOLDER/etl_csv_pipeline.py', '--cfg-path', '/var/folders/qd/tg0x144j35g7_hrcjsdscnrw0000gn/T/tmp_wdvrm69']
[2025-08-27T22:41:49.041+0500] {standard_task_runner.py:91} INFO - Job 6: Subtask transform_task
[2025-08-27T22:41:49.066+0500] {task_command.py:426} INFO - Running <TaskInstance: etl_csv_pipeline.transform_task manual__2025-08-27T17:41:30.969743+00:00 [running]> on host devs-macbook-pro-16.local
[2025-08-27T22:41:49.099+0500] {taskinstance.py:2648} INFO - Exporting env vars: AIRFLOW_CTX_DAG_EMAIL='junaidiqbalshah011@gmail.com' AIRFLOW_CTX_DAG_OWNER='airflow' AIRFLOW_CTX_DAG_ID='etl_csv_pipeline' AIRFLOW_CTX_TASK_ID='transform_task' AIRFLOW_CTX_EXECUTION_DATE='2025-08-27T17:41:30.969743+00:00' AIRFLOW_CTX_TRY_NUMBER='1' AIRFLOW_CTX_DAG_RUN_ID='manual__2025-08-27T17:41:30.969743+00:00'
[2025-08-27T22:41:49.100+0500] {taskinstance.py:430} INFO - ::endgroup::
[2025-08-27T22:41:51.872+0500] {taskinstance.py:441} INFO - ::group::Post task execution logs
[2025-08-27T22:41:51.872+0500] {taskinstance.py:2905} ERROR - Task failed with exception
Traceback (most recent call last):
  File "/Users/dev/Library/Python/3.9/lib/python/site-packages/airflow/models/taskinstance.py", line 465, in _execute_task
    result = _execute_callable(context=context, **execute_callable_kwargs)
  File "/Users/dev/Library/Python/3.9/lib/python/site-packages/airflow/models/taskinstance.py", line 432, in _execute_callable
    return execute_callable(context=context, **execute_callable_kwargs)
  File "/Users/dev/Library/Python/3.9/lib/python/site-packages/airflow/models/baseoperator.py", line 400, in wrapper
    return func(self, *args, **kwargs)
  File "/Users/dev/Library/Python/3.9/lib/python/site-packages/airflow/operators/python.py", line 235, in execute
    return_value = self.execute_callable()
  File "/Users/dev/Library/Python/3.9/lib/python/site-packages/airflow/operators/python.py", line 252, in execute_callable
    return self.python_callable(*self.op_args, **self.op_kwargs)
  File "/Users/dev/Desktop/workspace/Data-Engineering/Apache-Airflow/Day-01/dags/etl_csv_pipeline.py", line 15, in transform
    transformed_data = pd.DataFrame.from_dict(data)[['match_no']]
  File "/Users/dev/Library/Python/3.9/lib/python/site-packages/pandas/core/frame.py", line 4113, in __getitem__
    indexer = self.columns._get_indexer_strict(key, "columns")[1]
  File "/Users/dev/Library/Python/3.9/lib/python/site-packages/pandas/core/indexes/base.py", line 6212, in _get_indexer_strict
    self._raise_if_missing(keyarr, indexer, axis_name)
  File "/Users/dev/Library/Python/3.9/lib/python/site-packages/pandas/core/indexes/base.py", line 6261, in _raise_if_missing
    raise KeyError(f"None of [{key}] are in the [{axis_name}]")
KeyError: "None of [Index(['match_no'], dtype='object')] are in the [columns]"
[2025-08-27T22:41:51.899+0500] {taskinstance.py:1206} INFO - Marking task as UP_FOR_RETRY. dag_id=etl_csv_pipeline, task_id=transform_task, run_id=manual__2025-08-27T17:41:30.969743+00:00, execution_date=20250827T174130, start_date=20250827T174149, end_date=20250827T174151
[2025-08-27T22:41:51.904+0500] {standard_task_runner.py:110} ERROR - Failed to execute job 6 for task transform_task ("None of [Index(['match_no'], dtype='object')] are in the [columns]"; 74427)
[2025-08-27T22:41:51.952+0500] {local_task_job_runner.py:240} INFO - Task exited with return code 1
[2025-08-27T22:41:51.963+0500] {taskinstance.py:3498} INFO - 0 downstream tasks scheduled from follow-on schedule check
[2025-08-27T22:41:51.963+0500] {local_task_job_runner.py:222} INFO - ::endgroup::
