[2025-08-27T22:43:59.764+0500] {local_task_job_runner.py:120} INFO - ::group::Pre task execution logs
[2025-08-27T22:43:59.772+0500] {taskinstance.py:2076} INFO - Dependencies all met for dep_context=non-requeueable deps ti=<TaskInstance: etl_csv_pipeline.transform_task scheduled__2025-08-26T00:00:00+00:00 [queued]>
[2025-08-27T22:43:59.776+0500] {taskinstance.py:2076} INFO - Dependencies all met for dep_context=requeueable deps ti=<TaskInstance: etl_csv_pipeline.transform_task scheduled__2025-08-26T00:00:00+00:00 [queued]>
[2025-08-27T22:43:59.776+0500] {taskinstance.py:2306} INFO - Starting attempt 3 of 3
[2025-08-27T22:43:59.782+0500] {taskinstance.py:2330} INFO - Executing <Task(PythonOperator): transform_task> on 2025-08-26 00:00:00+00:00
[2025-08-27T22:43:59.789+0500] {standard_task_runner.py:63} INFO - Started process 76041 to run task
[2025-08-27T22:43:59.793+0500] {standard_task_runner.py:90} INFO - Running: ['airflow', 'tasks', 'run', 'etl_csv_pipeline', 'transform_task', 'scheduled__2025-08-26T00:00:00+00:00', '--job-id', '9', '--raw', '--subdir', 'DAGS_FOLDER/etl_csv_pipeline.py', '--cfg-path', '/var/folders/qd/tg0x144j35g7_hrcjsdscnrw0000gn/T/tmpxlwhlkbc']
[2025-08-27T22:43:59.794+0500] {standard_task_runner.py:91} INFO - Job 9: Subtask transform_task
[2025-08-27T22:43:59.821+0500] {task_command.py:426} INFO - Running <TaskInstance: etl_csv_pipeline.transform_task scheduled__2025-08-26T00:00:00+00:00 [running]> on host devs-macbook-pro-16.local
[2025-08-27T22:43:59.852+0500] {taskinstance.py:2648} INFO - Exporting env vars: AIRFLOW_CTX_DAG_EMAIL='junaidiqbalshah011@gmail.com' AIRFLOW_CTX_DAG_OWNER='airflow' AIRFLOW_CTX_DAG_ID='etl_csv_pipeline' AIRFLOW_CTX_TASK_ID='transform_task' AIRFLOW_CTX_EXECUTION_DATE='2025-08-26T00:00:00+00:00' AIRFLOW_CTX_TRY_NUMBER='3' AIRFLOW_CTX_DAG_RUN_ID='scheduled__2025-08-26T00:00:00+00:00'
[2025-08-27T22:43:59.853+0500] {taskinstance.py:430} INFO - ::endgroup::
[2025-08-27T22:44:02.846+0500] {taskinstance.py:441} INFO - ::group::Post task execution logs
[2025-08-27T22:44:02.846+0500] {taskinstance.py:2905} ERROR - Task failed with exception
Traceback (most recent call last):
  File "/Users/dev/Library/Python/3.9/lib/python/site-packages/airflow/models/taskinstance.py", line 465, in _execute_task
    result = _execute_callable(context=context, **execute_callable_kwargs)
  File "/Users/dev/Library/Python/3.9/lib/python/site-packages/airflow/models/taskinstance.py", line 432, in _execute_callable
    return execute_callable(context=context, **execute_callable_kwargs)
  File "/Users/dev/Library/Python/3.9/lib/python/site-packages/airflow/models/baseoperator.py", line 400, in wrapper
    return func(self, *args, **kwargs)
  File "/Users/dev/Library/Python/3.9/lib/python/site-packages/airflow/operators/python.py", line 235, in execute
    return_value = self.execute_callable()
  File "/Users/dev/Library/Python/3.9/lib/python/site-packages/airflow/operators/python.py", line 252, in execute_callable
    return self.python_callable(*self.op_args, **self.op_kwargs)
  File "/Users/dev/Desktop/workspace/Data-Engineering/Apache-Airflow/Day-01/dags/etl_csv_pipeline.py", line 15, in transform
    transformed_data = pd.DataFrame.from_dict(data)[['match_no']]
  File "/Users/dev/Library/Python/3.9/lib/python/site-packages/pandas/core/frame.py", line 4113, in __getitem__
    indexer = self.columns._get_indexer_strict(key, "columns")[1]
  File "/Users/dev/Library/Python/3.9/lib/python/site-packages/pandas/core/indexes/base.py", line 6212, in _get_indexer_strict
    self._raise_if_missing(keyarr, indexer, axis_name)
  File "/Users/dev/Library/Python/3.9/lib/python/site-packages/pandas/core/indexes/base.py", line 6261, in _raise_if_missing
    raise KeyError(f"None of [{key}] are in the [{axis_name}]")
KeyError: "None of [Index(['match_no'], dtype='object')] are in the [columns]"
[2025-08-27T22:44:02.880+0500] {taskinstance.py:1206} INFO - Marking task as FAILED. dag_id=etl_csv_pipeline, task_id=transform_task, run_id=scheduled__2025-08-26T00:00:00+00:00, execution_date=20250826T000000, start_date=20250827T174359, end_date=20250827T174402
[2025-08-27T22:44:02.893+0500] {logging_mixin.py:188} WARNING - /Users/dev/Library/Python/3.9/lib/python/site-packages/airflow/utils/email.py:154 RemovedInAirflow3Warning: Fetching SMTP credentials from configuration variables will be deprecated in a future release. Please set credentials using a connection instead.
[2025-08-27T22:44:02.893+0500] {configuration.py:1050} WARNING - section/key [smtp/smtp_user] not found in config
[2025-08-27T22:44:02.893+0500] {email.py:271} INFO - Email alerting: attempt 1
[2025-08-27T22:44:02.896+0500] {configuration.py:1050} WARNING - section/key [smtp/smtp_user] not found in config
[2025-08-27T22:44:02.897+0500] {email.py:271} INFO - Email alerting: attempt 1
[2025-08-27T22:44:02.897+0500] {taskinstance.py:879} ERROR - Failed to send email to: ['junaidiqbalshah011@gmail.com']
Traceback (most recent call last):
  File "/Users/dev/Library/Python/3.9/lib/python/site-packages/airflow/models/taskinstance.py", line 2479, in _run_raw_task
    self._execute_task_with_callbacks(context, test_mode, session=session)
  File "/Users/dev/Library/Python/3.9/lib/python/site-packages/airflow/models/taskinstance.py", line 2676, in _execute_task_with_callbacks
    result = self._execute_task(context, task_orig)
  File "/Users/dev/Library/Python/3.9/lib/python/site-packages/airflow/models/taskinstance.py", line 2701, in _execute_task
    return _execute_task(self, context, task_orig)
  File "/Users/dev/Library/Python/3.9/lib/python/site-packages/airflow/models/taskinstance.py", line 465, in _execute_task
    result = _execute_callable(context=context, **execute_callable_kwargs)
  File "/Users/dev/Library/Python/3.9/lib/python/site-packages/airflow/models/taskinstance.py", line 432, in _execute_callable
    return execute_callable(context=context, **execute_callable_kwargs)
  File "/Users/dev/Library/Python/3.9/lib/python/site-packages/airflow/models/baseoperator.py", line 400, in wrapper
    return func(self, *args, **kwargs)
  File "/Users/dev/Library/Python/3.9/lib/python/site-packages/airflow/operators/python.py", line 235, in execute
    return_value = self.execute_callable()
  File "/Users/dev/Library/Python/3.9/lib/python/site-packages/airflow/operators/python.py", line 252, in execute_callable
    return self.python_callable(*self.op_args, **self.op_kwargs)
  File "/Users/dev/Desktop/workspace/Data-Engineering/Apache-Airflow/Day-01/dags/etl_csv_pipeline.py", line 15, in transform
    transformed_data = pd.DataFrame.from_dict(data)[['match_no']]
  File "/Users/dev/Library/Python/3.9/lib/python/site-packages/pandas/core/frame.py", line 4113, in __getitem__
    indexer = self.columns._get_indexer_strict(key, "columns")[1]
  File "/Users/dev/Library/Python/3.9/lib/python/site-packages/pandas/core/indexes/base.py", line 6212, in _get_indexer_strict
    self._raise_if_missing(keyarr, indexer, axis_name)
  File "/Users/dev/Library/Python/3.9/lib/python/site-packages/pandas/core/indexes/base.py", line 6261, in _raise_if_missing
    raise KeyError(f"None of [{key}] are in the [{axis_name}]")
KeyError: "None of [Index(['match_no'], dtype='object')] are in the [columns]"

During handling of the above exception, another exception occurred:

Traceback (most recent call last):
  File "/Users/dev/Library/Python/3.9/lib/python/site-packages/airflow/models/taskinstance.py", line 1063, in _email_alert
    send_email(task.email, subject, html_content)
  File "/Users/dev/Library/Python/3.9/lib/python/site-packages/airflow/utils/email.py", line 80, in send_email
    return backend(
  File "/Users/dev/Library/Python/3.9/lib/python/site-packages/airflow/utils/email.py", line 154, in send_email_smtp
    send_mime_email(e_from=mail_from, e_to=recipients, mime_msg=msg, conn_id=conn_id, dryrun=dryrun)
  File "/Users/dev/Library/Python/3.9/lib/python/site-packages/airflow/utils/email.py", line 273, in send_mime_email
    smtp_conn = _get_smtp_connection(smtp_host, smtp_port, smtp_timeout, smtp_ssl)
  File "/Users/dev/Library/Python/3.9/lib/python/site-packages/airflow/utils/email.py", line 317, in _get_smtp_connection
    return smtplib.SMTP(host=host, port=port, timeout=timeout)
  File "/Library/Developer/CommandLineTools/Library/Frameworks/Python3.framework/Versions/3.9/lib/python3.9/smtplib.py", line 255, in __init__
    (code, msg) = self.connect(host, port)
  File "/Library/Developer/CommandLineTools/Library/Frameworks/Python3.framework/Versions/3.9/lib/python3.9/smtplib.py", line 341, in connect
    self.sock = self._get_socket(host, port, self.timeout)
  File "/Library/Developer/CommandLineTools/Library/Frameworks/Python3.framework/Versions/3.9/lib/python3.9/smtplib.py", line 312, in _get_socket
    return socket.create_connection((host, port), timeout,
  File "/Library/Developer/CommandLineTools/Library/Frameworks/Python3.framework/Versions/3.9/lib/python3.9/socket.py", line 843, in create_connection
    raise err
  File "/Library/Developer/CommandLineTools/Library/Frameworks/Python3.framework/Versions/3.9/lib/python3.9/socket.py", line 831, in create_connection
    sock.connect(sa)
ConnectionRefusedError: [Errno 61] Connection refused

During handling of the above exception, another exception occurred:

Traceback (most recent call last):
  File "/Users/dev/Library/Python/3.9/lib/python/site-packages/airflow/models/taskinstance.py", line 877, in _handle_failure
    task_instance.email_alert(error, failure_context["task"])
  File "/Users/dev/Library/Python/3.9/lib/python/site-packages/airflow/models/taskinstance.py", line 3163, in email_alert
    _email_alert(task_instance=self, exception=exception, task=task)
  File "/Users/dev/Library/Python/3.9/lib/python/site-packages/airflow/models/taskinstance.py", line 1065, in _email_alert
    send_email(task.email, subject, html_content_err)
  File "/Users/dev/Library/Python/3.9/lib/python/site-packages/airflow/utils/email.py", line 80, in send_email
    return backend(
  File "/Users/dev/Library/Python/3.9/lib/python/site-packages/airflow/utils/email.py", line 154, in send_email_smtp
    send_mime_email(e_from=mail_from, e_to=recipients, mime_msg=msg, conn_id=conn_id, dryrun=dryrun)
  File "/Users/dev/Library/Python/3.9/lib/python/site-packages/airflow/utils/email.py", line 273, in send_mime_email
    smtp_conn = _get_smtp_connection(smtp_host, smtp_port, smtp_timeout, smtp_ssl)
  File "/Users/dev/Library/Python/3.9/lib/python/site-packages/airflow/utils/email.py", line 317, in _get_smtp_connection
    return smtplib.SMTP(host=host, port=port, timeout=timeout)
  File "/Library/Developer/CommandLineTools/Library/Frameworks/Python3.framework/Versions/3.9/lib/python3.9/smtplib.py", line 255, in __init__
    (code, msg) = self.connect(host, port)
  File "/Library/Developer/CommandLineTools/Library/Frameworks/Python3.framework/Versions/3.9/lib/python3.9/smtplib.py", line 341, in connect
    self.sock = self._get_socket(host, port, self.timeout)
  File "/Library/Developer/CommandLineTools/Library/Frameworks/Python3.framework/Versions/3.9/lib/python3.9/smtplib.py", line 312, in _get_socket
    return socket.create_connection((host, port), timeout,
  File "/Library/Developer/CommandLineTools/Library/Frameworks/Python3.framework/Versions/3.9/lib/python3.9/socket.py", line 843, in create_connection
    raise err
  File "/Library/Developer/CommandLineTools/Library/Frameworks/Python3.framework/Versions/3.9/lib/python3.9/socket.py", line 831, in create_connection
    sock.connect(sa)
ConnectionRefusedError: [Errno 61] Connection refused
[2025-08-27T22:44:02.908+0500] {standard_task_runner.py:110} ERROR - Failed to execute job 9 for task transform_task ("None of [Index(['match_no'], dtype='object')] are in the [columns]"; 76041)
[2025-08-27T22:44:02.934+0500] {local_task_job_runner.py:240} INFO - Task exited with return code 1
[2025-08-27T22:44:02.950+0500] {taskinstance.py:3498} INFO - 0 downstream tasks scheduled from follow-on schedule check
[2025-08-27T22:44:02.953+0500] {local_task_job_runner.py:222} INFO - ::endgroup::
