[2025-08-26T22:39:02.441+0500] {local_task_job_runner.py:120} INFO - ::group::Pre task execution logs
[2025-08-26T22:39:02.449+0500] {taskinstance.py:2076} INFO - Dependencies all met for dep_context=non-requeueable deps ti=<TaskInstance: etl_csv_pipeline.extract_task manual__2025-08-26T17:37:56.399386+00:00 [queued]>
[2025-08-26T22:39:02.453+0500] {taskinstance.py:2076} INFO - Dependencies all met for dep_context=requeueable deps ti=<TaskInstance: etl_csv_pipeline.extract_task manual__2025-08-26T17:37:56.399386+00:00 [queued]>
[2025-08-26T22:39:02.453+0500] {taskinstance.py:2306} INFO - Starting attempt 2 of 3
[2025-08-26T22:39:02.458+0500] {taskinstance.py:2330} INFO - Executing <Task(PythonOperator): extract_task> on 2025-08-26 17:37:56.399386+00:00
[2025-08-26T22:39:02.464+0500] {standard_task_runner.py:63} INFO - Started process 16694 to run task
[2025-08-26T22:39:02.468+0500] {standard_task_runner.py:90} INFO - Running: ['airflow', 'tasks', 'run', 'etl_csv_pipeline', 'extract_task', 'manual__2025-08-26T17:37:56.399386+00:00', '--job-id', '6', '--raw', '--subdir', 'DAGS_FOLDER/etl_csv_pipeline.py', '--cfg-path', '/var/folders/qd/tg0x144j35g7_hrcjsdscnrw0000gn/T/tmpg4yn7160']
[2025-08-26T22:39:02.469+0500] {standard_task_runner.py:91} INFO - Job 6: Subtask extract_task
[2025-08-26T22:39:02.494+0500] {task_command.py:426} INFO - Running <TaskInstance: etl_csv_pipeline.extract_task manual__2025-08-26T17:37:56.399386+00:00 [running]> on host devs-macbook-pro-16.local
[2025-08-26T22:39:02.522+0500] {taskinstance.py:2648} INFO - Exporting env vars: AIRFLOW_CTX_DAG_OWNER='airflow' AIRFLOW_CTX_DAG_ID='etl_csv_pipeline' AIRFLOW_CTX_TASK_ID='extract_task' AIRFLOW_CTX_EXECUTION_DATE='2025-08-26T17:37:56.399386+00:00' AIRFLOW_CTX_TRY_NUMBER='2' AIRFLOW_CTX_DAG_RUN_ID='manual__2025-08-26T17:37:56.399386+00:00'
[2025-08-26T22:39:02.523+0500] {taskinstance.py:430} INFO - ::endgroup::
[2025-08-26T22:39:02.524+0500] {taskinstance.py:441} INFO - ::group::Post task execution logs
[2025-08-26T22:39:02.524+0500] {taskinstance.py:2905} ERROR - Task failed with exception
Traceback (most recent call last):
  File "/Users/dev/Library/Python/3.9/lib/python/site-packages/airflow/models/taskinstance.py", line 465, in _execute_task
    result = _execute_callable(context=context, **execute_callable_kwargs)
  File "/Users/dev/Library/Python/3.9/lib/python/site-packages/airflow/models/taskinstance.py", line 432, in _execute_callable
    return execute_callable(context=context, **execute_callable_kwargs)
  File "/Users/dev/Library/Python/3.9/lib/python/site-packages/airflow/models/baseoperator.py", line 400, in wrapper
    return func(self, *args, **kwargs)
  File "/Users/dev/Library/Python/3.9/lib/python/site-packages/airflow/operators/python.py", line 235, in execute
    return_value = self.execute_callable()
  File "/Users/dev/Library/Python/3.9/lib/python/site-packages/airflow/operators/python.py", line 252, in execute_callable
    return self.python_callable(*self.op_args, **self.op_kwargs)
  File "/Users/dev/Desktop/workspace/Data-Engineering/Apache-Airflow/Day-01/dags/etl_csv_pipeline.py", line 9, in extract
    df = pd.read_csv('/path/to/input.csv')
  File "/Users/dev/Library/Python/3.9/lib/python/site-packages/pandas/io/parsers/readers.py", line 1026, in read_csv
    return _read(filepath_or_buffer, kwds)
  File "/Users/dev/Library/Python/3.9/lib/python/site-packages/pandas/io/parsers/readers.py", line 620, in _read
    parser = TextFileReader(filepath_or_buffer, **kwds)
  File "/Users/dev/Library/Python/3.9/lib/python/site-packages/pandas/io/parsers/readers.py", line 1620, in __init__
    self._engine = self._make_engine(f, self.engine)
  File "/Users/dev/Library/Python/3.9/lib/python/site-packages/pandas/io/parsers/readers.py", line 1880, in _make_engine
    self.handles = get_handle(
  File "/Users/dev/Library/Python/3.9/lib/python/site-packages/pandas/io/common.py", line 873, in get_handle
    handle = open(
FileNotFoundError: [Errno 2] No such file or directory: '/path/to/input.csv'
[2025-08-26T22:39:02.547+0500] {taskinstance.py:1206} INFO - Marking task as UP_FOR_RETRY. dag_id=etl_csv_pipeline, task_id=extract_task, run_id=manual__2025-08-26T17:37:56.399386+00:00, execution_date=20250826T173756, start_date=20250826T173902, end_date=20250826T173902
[2025-08-26T22:39:02.551+0500] {standard_task_runner.py:110} ERROR - Failed to execute job 6 for task extract_task ([Errno 2] No such file or directory: '/path/to/input.csv'; 16694)
[2025-08-26T22:39:02.568+0500] {local_task_job_runner.py:240} INFO - Task exited with return code 1
[2025-08-26T22:39:02.579+0500] {taskinstance.py:3498} INFO - 0 downstream tasks scheduled from follow-on schedule check
[2025-08-26T22:39:02.579+0500] {local_task_job_runner.py:222} INFO - ::endgroup::
